2023-11-30 17:45:17.305359: I tensorflow/core/platform/cpu_feature_guard.cc:182] This TensorFlow binary is optimized to use available CPU instructions in performance-critical operations.
To enable the following instructions: AVX2 FMA, in other operations, rebuild TensorFlow with the appropriate compiler flags.
2023-11-30 17:45:18.096105: W tensorflow/compiler/tf2tensorrt/utils/py_utils.cc:38] TF-TRT Warning: Could not find TensorRT
No model was supplied, defaulted to distilbert-base-cased-distilled-squad and revision 626af31 (https://huggingface.co/distilbert-base-cased-distilled-squad).
Using a pipeline without specifying a model name and revision in production is not recommended.
Traceback (most recent call last):
  File "/root/autodl-tmp/conda-envs/py38/lib/python3.8/site-packages/huggingface_hub/utils/_errors.py", line 270, in hf_raise_for_status
    response.raise_for_status()
  File "/root/autodl-tmp/conda-envs/py38/lib/python3.8/site-packages/requests/models.py", line 1021, in raise_for_status
    raise HTTPError(http_error_msg, response=self)
requests.exceptions.HTTPError: 503 Server Error: Service Unavailable for url: https://huggingface.co/distilbert-base-cased-distilled-squad/resolve/main/config.json

The above exception was the direct cause of the following exception:

Traceback (most recent call last):
  File "/root/autodl-tmp/conda-envs/py38/lib/python3.8/site-packages/huggingface_hub/file_download.py", line 1247, in hf_hub_download
    metadata = get_hf_file_metadata(
  File "/root/autodl-tmp/conda-envs/py38/lib/python3.8/site-packages/huggingface_hub/utils/_validators.py", line 118, in _inner_fn
    return fn(*args, **kwargs)
  File "/root/autodl-tmp/conda-envs/py38/lib/python3.8/site-packages/huggingface_hub/file_download.py", line 1624, in get_hf_file_metadata
    r = _request_wrapper(
  File "/root/autodl-tmp/conda-envs/py38/lib/python3.8/site-packages/huggingface_hub/file_download.py", line 402, in _request_wrapper
    response = _request_wrapper(
  File "/root/autodl-tmp/conda-envs/py38/lib/python3.8/site-packages/huggingface_hub/file_download.py", line 426, in _request_wrapper
    hf_raise_for_status(response)
  File "/root/autodl-tmp/conda-envs/py38/lib/python3.8/site-packages/huggingface_hub/utils/_errors.py", line 330, in hf_raise_for_status
    raise HfHubHTTPError(str(e), response=response) from e
huggingface_hub.utils._errors.HfHubHTTPError: 503 Server Error: Service Unavailable for url: https://huggingface.co/distilbert-base-cased-distilled-squad/resolve/main/config.json

The above exception was the direct cause of the following exception:

Traceback (most recent call last):
  File "/root/autodl-tmp/conda-envs/py38/lib/python3.8/site-packages/transformers/utils/hub.py", line 430, in cached_file
    resolved_file = hf_hub_download(
  File "/root/autodl-tmp/conda-envs/py38/lib/python3.8/site-packages/huggingface_hub/utils/_validators.py", line 118, in _inner_fn
    return fn(*args, **kwargs)
  File "/root/autodl-tmp/conda-envs/py38/lib/python3.8/site-packages/huggingface_hub/file_download.py", line 1377, in hf_hub_download
    raise LocalEntryNotFoundError(
huggingface_hub.utils._errors.LocalEntryNotFoundError: An error happened while trying to locate the file on the Hub and we cannot find the requested files in the local cache. Please check your connection and try again or make sure your Internet connection is on.

The above exception was the direct cause of the following exception:

Traceback (most recent call last):
  File "./f00135_get_game_day.py", line 39, in <module>
    test_get_game_day()
  File "./f00135_get_game_day.py", line 31, in test_get_game_day
    assert get_game_day("The game was played on February 7, 2016 at Levi's Stadium in the San Francisco Bay Area at Santa Clara, California.", "What day was the game played on?") == 'February 7, 2016'
  File "./f00135_get_game_day.py", line 20, in get_game_day
    nlp = pipeline('question-answering')
  File "/root/autodl-tmp/conda-envs/py38/lib/python3.8/site-packages/transformers/pipelines/__init__.py", line 841, in pipeline
    config = AutoConfig.from_pretrained(model, _from_pipeline=task, **hub_kwargs, **model_kwargs)
  File "/root/autodl-tmp/conda-envs/py38/lib/python3.8/site-packages/transformers/models/auto/configuration_auto.py", line 1048, in from_pretrained
    config_dict, unused_kwargs = PretrainedConfig.get_config_dict(pretrained_model_name_or_path, **kwargs)
  File "/root/autodl-tmp/conda-envs/py38/lib/python3.8/site-packages/transformers/configuration_utils.py", line 622, in get_config_dict
    config_dict, kwargs = cls._get_config_dict(pretrained_model_name_or_path, **kwargs)
  File "/root/autodl-tmp/conda-envs/py38/lib/python3.8/site-packages/transformers/configuration_utils.py", line 677, in _get_config_dict
    resolved_config_file = cached_file(
  File "/root/autodl-tmp/conda-envs/py38/lib/python3.8/site-packages/transformers/utils/hub.py", line 470, in cached_file
    raise EnvironmentError(
OSError: We couldn't connect to 'https://huggingface.co' to load this file, couldn't find it in the cached files and it looks like distilbert-base-cased-distilled-squad is not the path to a directory containing a file named config.json.
Checkout your internet connection or see how to run the library in offline mode at 'https://huggingface.co/docs/transformers/installation#offline-mode'.
