Downloading (…)ve/main/spiece.model:   0%|                               | 0.00/1.91M [00:00<?, ?B/s]Downloading (…)ve/main/spiece.model: 100%|███████████████████████| 1.91M/1.91M [00:10<00:00, 188kB/s]Downloading (…)ve/main/spiece.model: 100%|███████████████████████| 1.91M/1.91M [00:10<00:00, 188kB/s]
Downloading (…)cial_tokens_map.json:   0%|                                | 0.00/65.0 [00:00<?, ?B/s]Downloading (…)cial_tokens_map.json: 100%|████████████████████████| 65.0/65.0 [00:00<00:00, 18.3kB/s]
Downloading (…)okenizer_config.json:   0%|                                | 0.00/88.0 [00:00<?, ?B/s]Downloading (…)okenizer_config.json: 100%|█████████████████████████| 88.0/88.0 [00:00<00:00, 115kB/s]
Downloading (…)lve/main/config.json:   0%|                               | 0.00/1.12k [00:00<?, ?B/s]Downloading (…)lve/main/config.json: 100%|██████████████████████| 1.12k/1.12k [00:00<00:00, 1.32MB/s]
Downloading pytorch_model.bin:   0%|                                     | 0.00/2.28G [00:00<?, ?B/s]Downloading pytorch_model.bin:   0%|                           | 10.5M/2.28G [01:08<4:05:44, 154kB/s]Downloading pytorch_model.bin:   0%|                           | 10.5M/2.28G [01:22<4:05:44, 154kB/s]Traceback (most recent call last):
  File "/root/miniconda3/envs/py38/lib/python3.8/site-packages/urllib3/response.py", line 710, in _error_catcher
    yield
  File "/root/miniconda3/envs/py38/lib/python3.8/site-packages/urllib3/response.py", line 835, in _raw_read
    raise IncompleteRead(self._fp_bytes_read, self.length_remaining)
urllib3.exceptions.IncompleteRead: IncompleteRead(15666459 bytes read, 2259661424 more expected)

The above exception was the direct cause of the following exception:

Traceback (most recent call last):
  File "/root/miniconda3/envs/py38/lib/python3.8/site-packages/requests/models.py", line 816, in generate
    yield from self.raw.stream(chunk_size, decode_content=True)
  File "/root/miniconda3/envs/py38/lib/python3.8/site-packages/urllib3/response.py", line 940, in stream
    data = self.read(amt=amt, decode_content=decode_content)
  File "/root/miniconda3/envs/py38/lib/python3.8/site-packages/urllib3/response.py", line 911, in read
    data = self._raw_read(amt)
  File "/root/miniconda3/envs/py38/lib/python3.8/site-packages/urllib3/response.py", line 835, in _raw_read
    raise IncompleteRead(self._fp_bytes_read, self.length_remaining)
  File "/root/miniconda3/envs/py38/lib/python3.8/contextlib.py", line 131, in __exit__
    self.gen.throw(type, value, traceback)
  File "/root/miniconda3/envs/py38/lib/python3.8/site-packages/urllib3/response.py", line 727, in _error_catcher
    raise ProtocolError(f"Connection broken: {e!r}", e) from e
urllib3.exceptions.ProtocolError: ('Connection broken: IncompleteRead(15666459 bytes read, 2259661424 more expected)', IncompleteRead(15666459 bytes read, 2259661424 more expected))

During handling of the above exception, another exception occurred:

Traceback (most recent call last):
  File "output/hf-eval-data-v2/f00059_summarize_text.py", line 37, in <module>
    test_summarize_text()
  File "output/hf-eval-data-v2/f00059_summarize_text.py", line 32, in test_summarize_text
    summary = summarize_text(input_text)
  File "output/hf-eval-data-v2/f00059_summarize_text.py", line 19, in summarize_text
    model = PegasusForConditionalGeneration.from_pretrained(model_name)
  File "/root/miniconda3/envs/py38/lib/python3.8/site-packages/transformers/modeling_utils.py", line 2793, in from_pretrained
    resolved_archive_file = cached_file(
  File "/root/miniconda3/envs/py38/lib/python3.8/site-packages/transformers/utils/hub.py", line 429, in cached_file
    resolved_file = hf_hub_download(
  File "/root/miniconda3/envs/py38/lib/python3.8/site-packages/huggingface_hub/utils/_validators.py", line 118, in _inner_fn
    return fn(*args, **kwargs)
  File "/root/miniconda3/envs/py38/lib/python3.8/site-packages/huggingface_hub/file_download.py", line 1429, in hf_hub_download
    http_get(
  File "/root/miniconda3/envs/py38/lib/python3.8/site-packages/huggingface_hub/file_download.py", line 551, in http_get
    for chunk in r.iter_content(chunk_size=10 * 1024 * 1024):
  File "/root/miniconda3/envs/py38/lib/python3.8/site-packages/requests/models.py", line 818, in generate
    raise ChunkedEncodingError(e)
requests.exceptions.ChunkedEncodingError: ('Connection broken: IncompleteRead(15666459 bytes read, 2259661424 more expected)', IncompleteRead(15666459 bytes read, 2259661424 more expected))
Downloading pytorch_model.bin:   0%|                           | 10.5M/2.28G [01:38<5:55:53, 106kB/s]