Traceback (most recent call last):
  File "output/hf-eval-data-v2/f00592_get_answer.py", line 38, in <module>
    test_get_answer()
  File "output/hf-eval-data-v2/f00592_get_answer.py", line 32, in test_get_answer
    answer = get_answer(context, question)
  File "output/hf-eval-data-v2/f00592_get_answer.py", line 19, in get_answer
    qa_pipeline = pipeline('question-answering', model='bert-large-cased-whole-word-masking-finetuned-squad')
  File "/root/miniconda3/envs/py38/lib/python3.8/site-packages/transformers/pipelines/__init__.py", line 729, in pipeline
    maybe_adapter_path = find_adapter_config_file(
  File "/root/miniconda3/envs/py38/lib/python3.8/site-packages/transformers/utils/peft_utils.py", line 87, in find_adapter_config_file
    adapter_cached_filename = cached_file(
  File "/root/miniconda3/envs/py38/lib/python3.8/site-packages/transformers/utils/hub.py", line 429, in cached_file
    resolved_file = hf_hub_download(
  File "/root/miniconda3/envs/py38/lib/python3.8/site-packages/huggingface_hub/utils/_validators.py", line 118, in _inner_fn
    return fn(*args, **kwargs)
  File "/root/miniconda3/envs/py38/lib/python3.8/site-packages/huggingface_hub/file_download.py", line 1193, in hf_hub_download
    os.makedirs(storage_folder, exist_ok=True)
  File "/root/miniconda3/envs/py38/lib/python3.8/os.py", line 223, in makedirs
    mkdir(name, mode)
OSError: [Errno 122] Disk quota exceeded: '/root/autodl-tmp/.cache/huggingface/hub/models--bert-large-cased-whole-word-masking-finetuned-squad'
