Traceback (most recent call last):
  File "output/hf-eval-data-v2/f00780_classify_inquiry.py", line 34, in <module>
    test_classify_inquiry()
  File "output/hf-eval-data-v2/f00780_classify_inquiry.py", line 30, in test_classify_inquiry
    assert classify_inquiry(test_inquiry) == expected_result
  File "output/hf-eval-data-v2/f00780_classify_inquiry.py", line 17, in classify_inquiry
    classifier = pipeline('zero-shot-classification', model='joeddav/xlm-roberta-large-xnli')
  File "/root/miniconda3/envs/py38/lib/python3.8/site-packages/transformers/pipelines/__init__.py", line 729, in pipeline
    maybe_adapter_path = find_adapter_config_file(
  File "/root/miniconda3/envs/py38/lib/python3.8/site-packages/transformers/utils/peft_utils.py", line 87, in find_adapter_config_file
    adapter_cached_filename = cached_file(
  File "/root/miniconda3/envs/py38/lib/python3.8/site-packages/transformers/utils/hub.py", line 429, in cached_file
    resolved_file = hf_hub_download(
  File "/root/miniconda3/envs/py38/lib/python3.8/site-packages/huggingface_hub/utils/_validators.py", line 118, in _inner_fn
    return fn(*args, **kwargs)
  File "/root/miniconda3/envs/py38/lib/python3.8/site-packages/huggingface_hub/file_download.py", line 1193, in hf_hub_download
    os.makedirs(storage_folder, exist_ok=True)
  File "/root/miniconda3/envs/py38/lib/python3.8/os.py", line 223, in makedirs
    mkdir(name, mode)
OSError: [Errno 122] Disk quota exceeded: '/root/autodl-tmp/.cache/huggingface/hub/models--joeddav--xlm-roberta-large-xnli'
