config.json:   0%|                                                                  | 0.00/1.39k [00:00<?, ?B/s]config.json: 100%|██████████████████████████████████████████████████████████| 1.39k/1.39k [00:00<00:00, 336kB/s]
pytorch_model.bin:   0%|                                                            | 0.00/1.02G [00:00<?, ?B/s]pytorch_model.bin:   1%|▌                                                   | 10.5M/1.02G [00:34<56:20, 300kB/s]pytorch_model.bin:   1%|▌                                                   | 10.5M/1.02G [00:45<56:20, 300kB/s]pytorch_model.bin:   2%|█                                                 | 21.0M/1.02G [01:47<1:30:46, 184kB/s]pytorch_model.bin:   2%|█                                                 | 21.0M/1.02G [02:05<1:30:46, 184kB/s]pytorch_model.bin:   3%|█▌                                                | 31.5M/1.02G [02:57<1:39:17, 167kB/s]pytorch_model.bin:   3%|█▌                                                | 31.5M/1.02G [03:15<1:39:17, 167kB/s]pytorch_model.bin:   4%|██                                                | 41.7M/1.02G [04:06<1:42:51, 159kB/s]pytorch_model.bin:   4%|██                                                | 41.7M/1.02G [04:06<1:36:40, 169kB/s]
Traceback (most recent call last):
  File "./f00687_classify_text.py", line 57, in <module>
    test_classify_text()
  File "./f00687_classify_text.py", line 39, in test_classify_text
    result = classify_text(text_message, categories)
  File "./f00687_classify_text.py", line 20, in classify_text
    model = AutoModelForSequenceClassification.from_pretrained(
  File "/root/autodl-tmp/conda-envs/py38/lib/python3.8/site-packages/transformers/models/auto/auto_factory.py", line 566, in from_pretrained
    return model_class.from_pretrained(
  File "/root/autodl-tmp/conda-envs/py38/lib/python3.8/site-packages/transformers/modeling_utils.py", line 3057, in from_pretrained
    resolved_archive_file = cached_file(
  File "/root/autodl-tmp/conda-envs/py38/lib/python3.8/site-packages/transformers/utils/hub.py", line 430, in cached_file
    resolved_file = hf_hub_download(
  File "/root/autodl-tmp/conda-envs/py38/lib/python3.8/site-packages/huggingface_hub/utils/_validators.py", line 118, in _inner_fn
    return fn(*args, **kwargs)
  File "/root/autodl-tmp/conda-envs/py38/lib/python3.8/site-packages/huggingface_hub/file_download.py", line 1461, in hf_hub_download
    http_get(
  File "/root/autodl-tmp/conda-envs/py38/lib/python3.8/site-packages/huggingface_hub/file_download.py", line 569, in http_get
    raise EnvironmentError(
OSError: Consistency check failed: file should be of size 1024804435 but has size 41729466 (pytorch_model.bin).
We are sorry for the inconvenience. Please retry download and pass `force_download=True, resume_download=False` as argument.
If the issue persists, please let us know by opening an issue on https://github.com/huggingface/huggingface_hub.
