Traceback (most recent call last):
  File "/root/miniconda3/envs/py38/lib/python3.8/site-packages/huggingface_hub/utils/_errors.py", line 261, in hf_raise_for_status
    response.raise_for_status()
  File "/root/miniconda3/envs/py38/lib/python3.8/site-packages/requests/models.py", line 1021, in raise_for_status
    raise HTTPError(http_error_msg, response=self)
requests.exceptions.HTTPError: 404 Client Error: Not Found for url: https://huggingface.co/microsoft/BiomedCLIP-PubMedBERT_256-vit_base_patch16_224/resolve/main/config.json

The above exception was the direct cause of the following exception:

Traceback (most recent call last):
  File "/root/miniconda3/envs/py38/lib/python3.8/site-packages/transformers/utils/hub.py", line 429, in cached_file
    resolved_file = hf_hub_download(
  File "/root/miniconda3/envs/py38/lib/python3.8/site-packages/huggingface_hub/utils/_validators.py", line 118, in _inner_fn
    return fn(*args, **kwargs)
  File "/root/miniconda3/envs/py38/lib/python3.8/site-packages/huggingface_hub/file_download.py", line 1230, in hf_hub_download
    metadata = get_hf_file_metadata(
  File "/root/miniconda3/envs/py38/lib/python3.8/site-packages/huggingface_hub/utils/_validators.py", line 118, in _inner_fn
    return fn(*args, **kwargs)
  File "/root/miniconda3/envs/py38/lib/python3.8/site-packages/huggingface_hub/file_download.py", line 1606, in get_hf_file_metadata
    hf_raise_for_status(r)
  File "/root/miniconda3/envs/py38/lib/python3.8/site-packages/huggingface_hub/utils/_errors.py", line 271, in hf_raise_for_status
    raise EntryNotFoundError(message, response) from e
huggingface_hub.utils._errors.EntryNotFoundError: 404 Client Error. (Request ID: Root=1-654e7fca-6f6187a61c4d0b787b3f6bb1;a1bde6b8-415a-430e-9f73-279ba9972092)

Entry Not Found for url: https://huggingface.co/microsoft/BiomedCLIP-PubMedBERT_256-vit_base_patch16_224/resolve/main/config.json.

The above exception was the direct cause of the following exception:

Traceback (most recent call last):
  File "./f00032_classify_medical_image.py", line 62, in <module>
    test_classify_medical_image()
  File "./f00032_classify_medical_image.py", line 43, in test_classify_medical_image
    result = classify_medical_image(image_url, possible_class_names)
  File "./f00032_classify_medical_image.py", line 30, in classify_medical_image
    clip = pipeline('zero-shot-image-classification', model='microsoft/BiomedCLIP-PubMedBERT_256-vit_base_patch16_224')
  File "/root/miniconda3/envs/py38/lib/python3.8/site-packages/transformers/pipelines/__init__.py", line 741, in pipeline
    config = AutoConfig.from_pretrained(model, _from_pipeline=task, **hub_kwargs, **model_kwargs)
  File "/root/miniconda3/envs/py38/lib/python3.8/site-packages/transformers/models/auto/configuration_auto.py", line 1023, in from_pretrained
    config_dict, unused_kwargs = PretrainedConfig.get_config_dict(pretrained_model_name_or_path, **kwargs)
  File "/root/miniconda3/envs/py38/lib/python3.8/site-packages/transformers/configuration_utils.py", line 620, in get_config_dict
    config_dict, kwargs = cls._get_config_dict(pretrained_model_name_or_path, **kwargs)
  File "/root/miniconda3/envs/py38/lib/python3.8/site-packages/transformers/configuration_utils.py", line 675, in _get_config_dict
    resolved_config_file = cached_file(
  File "/root/miniconda3/envs/py38/lib/python3.8/site-packages/transformers/utils/hub.py", line 480, in cached_file
    raise EnvironmentError(
OSError: microsoft/BiomedCLIP-PubMedBERT_256-vit_base_patch16_224 does not appear to have a file named config.json. Checkout 'https://huggingface.co/microsoft/BiomedCLIP-PubMedBERT_256-vit_base_patch16_224/main' for available files.
