Downloading (…)lve/main/config.json:   0%|                                                                           | 0.00/789 [00:00<?, ?B/s]Downloading (…)lve/main/config.json: 100%|████████████████████████████████████████████████████████████████████| 789/789 [00:00<00:00, 72.1kB/s]
Downloading model.safetensors:   0%|                                                                                | 0.00/511M [00:00<?, ?B/s]Downloading model.safetensors:   2%|█▍                                                                     | 10.5M/511M [00:06<04:54, 1.70MB/s]Downloading model.safetensors:   2%|█▍                                                                     | 10.5M/511M [00:24<04:54, 1.70MB/s]Traceback (most recent call last):
  File "/root/miniconda3/envs/py38/lib/python3.8/site-packages/urllib3/response.py", line 444, in _error_catcher
    yield
  File "/root/miniconda3/envs/py38/lib/python3.8/site-packages/urllib3/response.py", line 567, in read
    data = self._fp_read(amt) if not fp_closed else b""
  File "/root/miniconda3/envs/py38/lib/python3.8/site-packages/urllib3/response.py", line 533, in _fp_read
    return self._fp.read(amt) if amt is not None else self._fp.read()
  File "/root/miniconda3/envs/py38/lib/python3.8/http/client.py", line 459, in read
    n = self.readinto(b)
  File "/root/miniconda3/envs/py38/lib/python3.8/http/client.py", line 503, in readinto
    n = self.fp.readinto(b)
  File "/root/miniconda3/envs/py38/lib/python3.8/socket.py", line 669, in readinto
    return self._sock.recv_into(b)
  File "/root/miniconda3/envs/py38/lib/python3.8/ssl.py", line 1274, in recv_into
    return self.read(nbytes, buffer)
  File "/root/miniconda3/envs/py38/lib/python3.8/ssl.py", line 1132, in read
    return self._sslobj.read(len, buffer)
socket.timeout: The read operation timed out

During handling of the above exception, another exception occurred:

Traceback (most recent call last):
  File "/root/miniconda3/envs/py38/lib/python3.8/site-packages/requests/models.py", line 816, in generate
    yield from self.raw.stream(chunk_size, decode_content=True)
  File "/root/miniconda3/envs/py38/lib/python3.8/site-packages/urllib3/response.py", line 628, in stream
    data = self.read(amt=amt, decode_content=decode_content)
  File "/root/miniconda3/envs/py38/lib/python3.8/site-packages/urllib3/response.py", line 593, in read
    raise IncompleteRead(self._fp_bytes_read, self.length_remaining)
  File "/root/miniconda3/envs/py38/lib/python3.8/contextlib.py", line 131, in __exit__
    self.gen.throw(type, value, traceback)
  File "/root/miniconda3/envs/py38/lib/python3.8/site-packages/urllib3/response.py", line 449, in _error_catcher
    raise ReadTimeoutError(self._pool, None, "Read timed out.")
urllib3.exceptions.ReadTimeoutError: HTTPSConnectionPool(host='cdn-lfs.huggingface.co', port=443): Read timed out.

During handling of the above exception, another exception occurred:

Traceback (most recent call last):
  File "./f00102_document_question_answering.py", line 38, in <module>
    test_document_question_answering()
  File "./f00102_document_question_answering.py", line 31, in test_document_question_answering
    result = document_question_answering(image_url, question)
  File "./f00102_document_question_answering.py", line 19, in document_question_answering
    nlp = pipeline('question-answering', model=LayoutLMForQuestionAnswering.from_pretrained('impira/layoutlm-document-qa', return_dict=True))
  File "/root/miniconda3/envs/py38/lib/python3.8/site-packages/transformers/modeling_utils.py", line 2773, in from_pretrained
    resolved_archive_file = cached_file(pretrained_model_name_or_path, filename, **cached_file_kwargs)
  File "/root/miniconda3/envs/py38/lib/python3.8/site-packages/transformers/utils/hub.py", line 429, in cached_file
    resolved_file = hf_hub_download(
  File "/root/miniconda3/envs/py38/lib/python3.8/site-packages/huggingface_hub/utils/_validators.py", line 118, in _inner_fn
    return fn(*args, **kwargs)
  File "/root/miniconda3/envs/py38/lib/python3.8/site-packages/huggingface_hub/file_download.py", line 1429, in hf_hub_download
    http_get(
  File "/root/miniconda3/envs/py38/lib/python3.8/site-packages/huggingface_hub/file_download.py", line 551, in http_get
    for chunk in r.iter_content(chunk_size=10 * 1024 * 1024):
  File "/root/miniconda3/envs/py38/lib/python3.8/site-packages/requests/models.py", line 822, in generate
    raise ConnectionError(e)
requests.exceptions.ConnectionError: HTTPSConnectionPool(host='cdn-lfs.huggingface.co', port=443): Read timed out.
Downloading model.safetensors:   2%|█▍                                                                      | 10.5M/511M [00:28<22:57, 363kB/s]