Traceback (most recent call last):
  File "/root/miniconda3/envs/py38/lib/python3.8/site-packages/urllib3/connectionpool.py", line 715, in urlopen
    httplib_response = self._make_request(
  File "/root/miniconda3/envs/py38/lib/python3.8/site-packages/urllib3/connectionpool.py", line 467, in _make_request
    six.raise_from(e, None)
  File "<string>", line 3, in raise_from
  File "/root/miniconda3/envs/py38/lib/python3.8/site-packages/urllib3/connectionpool.py", line 462, in _make_request
    httplib_response = conn.getresponse()
  File "/root/miniconda3/envs/py38/lib/python3.8/site-packages/sentry_sdk/integrations/stdlib.py", line 128, in getresponse
    rv = real_getresponse(self, *args, **kwargs)
  File "/root/miniconda3/envs/py38/lib/python3.8/http/client.py", line 1348, in getresponse
    response.begin()
  File "/root/miniconda3/envs/py38/lib/python3.8/http/client.py", line 316, in begin
    version, status, reason = self._read_status()
  File "/root/miniconda3/envs/py38/lib/python3.8/http/client.py", line 285, in _read_status
    raise RemoteDisconnected("Remote end closed connection without"
http.client.RemoteDisconnected: Remote end closed connection without response

During handling of the above exception, another exception occurred:

Traceback (most recent call last):
  File "/root/miniconda3/envs/py38/lib/python3.8/site-packages/requests/adapters.py", line 486, in send
    resp = conn.urlopen(
  File "/root/miniconda3/envs/py38/lib/python3.8/site-packages/urllib3/connectionpool.py", line 799, in urlopen
    retries = retries.increment(
  File "/root/miniconda3/envs/py38/lib/python3.8/site-packages/urllib3/util/retry.py", line 592, in increment
    raise MaxRetryError(_pool, url, error or ResponseError(cause))
urllib3.exceptions.MaxRetryError: HTTPSConnectionPool(host='huggingface.co', port=443): Max retries exceeded with url: /api/models/keremberke/yolov8m-blood-cell-detection/tree/main?recursive=True&expand=False (Caused by ProxyError('Cannot connect to proxy.', RemoteDisconnected('Remote end closed connection without response')))

During handling of the above exception, another exception occurred:

Traceback (most recent call last):
  File "./f00277_detect_blood_cells.py", line 43, in <module>
    test_detect_blood_cells()
  File "./f00277_detect_blood_cells.py", line 36, in test_detect_blood_cells
    results = detect_blood_cells(image_path)
  File "./f00277_detect_blood_cells.py", line 17, in detect_blood_cells
    model = YOLO('keremberke/yolov8m-blood-cell-detection')
  File "/root/miniconda3/envs/py38/lib/python3.8/site-packages/ultralyticsplus/ultralytics_utils.py", line 46, in __init__
    self._load_from_hf_hub(model, hf_token=hf_token)
  File "/root/miniconda3/envs/py38/lib/python3.8/site-packages/ultralyticsplus/ultralytics_utils.py", line 59, in _load_from_hf_hub
    weights = download_from_hub(weights, hf_token=hf_token)
  File "/root/miniconda3/envs/py38/lib/python3.8/site-packages/ultralyticsplus/hf_utils.py", line 566, in download_from_hub
    repo_files = list_repo_files(repo_id=hf_model_id, repo_type="model", token=hf_token)
  File "/root/miniconda3/envs/py38/lib/python3.8/site-packages/huggingface_hub/utils/_deprecation.py", line 101, in inner_f
    return f(*args, **kwargs)
  File "/root/miniconda3/envs/py38/lib/python3.8/site-packages/huggingface_hub/utils/_validators.py", line 118, in _inner_fn
    return fn(*args, **kwargs)
  File "/root/miniconda3/envs/py38/lib/python3.8/site-packages/huggingface_hub/hf_api.py", line 2213, in list_repo_files
    return [
  File "/root/miniconda3/envs/py38/lib/python3.8/site-packages/huggingface_hub/hf_api.py", line 2213, in <listcomp>
    return [
  File "/root/miniconda3/envs/py38/lib/python3.8/site-packages/huggingface_hub/hf_api.py", line 2179, in list_files_info
    for subpath_info in paginate(path=tree_url, headers=headers, params={"recursive": True, "expand": expand}):
  File "/root/miniconda3/envs/py38/lib/python3.8/site-packages/huggingface_hub/utils/_pagination.py", line 35, in paginate
    r = session.get(path, params=params, headers=headers)
  File "/root/miniconda3/envs/py38/lib/python3.8/site-packages/requests/sessions.py", line 602, in get
    return self.request("GET", url, **kwargs)
  File "/root/miniconda3/envs/py38/lib/python3.8/site-packages/requests/sessions.py", line 589, in request
    resp = self.send(prep, **send_kwargs)
  File "/root/miniconda3/envs/py38/lib/python3.8/site-packages/requests/sessions.py", line 703, in send
    r = adapter.send(request, **kwargs)
  File "/root/miniconda3/envs/py38/lib/python3.8/site-packages/huggingface_hub/utils/_http.py", line 63, in send
    return super().send(request, *args, **kwargs)
  File "/root/miniconda3/envs/py38/lib/python3.8/site-packages/requests/adapters.py", line 513, in send
    raise ProxyError(e, request=request)
requests.exceptions.ProxyError: (MaxRetryError("HTTPSConnectionPool(host='huggingface.co', port=443): Max retries exceeded with url: /api/models/keremberke/yolov8m-blood-cell-detection/tree/main?recursive=True&expand=False (Caused by ProxyError('Cannot connect to proxy.', RemoteDisconnected('Remote end closed connection without response')))"), '(Request ID: 2449a7b0-7078-469f-a966-e046fa26aea7)')
Sentry is attempting to send 2 pending events
Waiting up to 2 seconds
Press Ctrl-C to quit
11/11/2023 18:10:11 - WARNING - urllib3.connectionpool -   Retrying (Retry(total=2, connect=None, read=None, redirect=None, status=None)) after connection broken by 'SSLError(SSLCertVerificationError(1, '[SSL: CERTIFICATE_VERIFY_FAILED] certificate verify failed: self-signed certificate in certificate chain (_ssl.c:1131)'))': /api/4504521592406016/envelope/
11/11/2023 18:10:12 - WARNING - urllib3.connectionpool -   Retrying (Retry(total=1, connect=None, read=None, redirect=None, status=None)) after connection broken by 'SSLError(SSLCertVerificationError(1, '[SSL: CERTIFICATE_VERIFY_FAILED] certificate verify failed: self-signed certificate in certificate chain (_ssl.c:1131)'))': /api/4504521592406016/envelope/
