Downloading (…)lve/main/config.json:   0%|                                                                           | 0.00/693 [00:00<?, ?B/s]Downloading (…)lve/main/config.json: 100%|████████████████████████████████████████████████████████████████████| 693/693 [00:00<00:00, 74.9kB/s]
'(MaxRetryError("HTTPSConnectionPool(host='cdn-lfs.huggingface.co', port=443): Max retries exceeded with url: /repos/76/61/766109d3d0b4ee837dfedfab0527ead28aab8af261c2eacbb3c7f7e5d3676920/a8702498162c95d68d2724e7f333c83d7be08de81cfc091455c38730682116d3?response-content-disposition=attachment%3B+filename*%3DUTF-8%27%27model.safetensors%3B+filename%3D%22model.safetensors%22%3B&Expires=1699957534&Policy=eyJTdGF0ZW1lbnQiOlt7IkNvbmRpdGlvbiI6eyJEYXRlTGVzc1RoYW4iOnsiQVdTOkVwb2NoVGltZSI6MTY5OTk1NzUzNH19LCJSZXNvdXJjZSI6Imh0dHBzOi8vY2RuLWxmcy5odWdnaW5nZmFjZS5jby9yZXBvcy83Ni82MS83NjYxMDlkM2QwYjRlZTgzN2RmZWRmYWIwNTI3ZWFkMjhhYWI4YWYyNjFjMmVhY2JiM2M3ZjdlNWQzNjc2OTIwL2E4NzAyNDk4MTYyYzk1ZDY4ZDI3MjRlN2YzMzNjODNkN2JlMDhkZTgxY2ZjMDkxNDU1YzM4NzMwNjgyMTE2ZDM~cmVzcG9uc2UtY29udGVudC1kaXNwb3NpdGlvbj0qIn1dfQ__&Signature=i5kimBqXmYWtdf51gu4VaAOWpTuLRxhB76R2ER4mL9v~Rigg7U~hYJl6Db1lUT39xOo6VddwNnKCwyrNG8wJI4hBPgzWoCnb0TSsm~9k1fMG57ommM0g3iEfNc58nEeKZtpW~uMgxgz54XVIiDozNIMGAT4UKbPvx9tVvosKHkrL890T3LWG-mFt65~knuRqSIM3EYtH71ve6r92llPK-T84l7zzUp8KxKQ8BPIBB7~3p5Oe-ArCyhWMoPbmthhjdYWZjMnm6u8fyioWBVs8Xvsrb6pExuD3eiBTPr7PfC4~s~jZB2nEoqyQZfItkt94djcNI2P255E~ZoAZVL1XKA__&Key-Pair-Id=KVTP0A1DKRTAX (Caused by ProxyError('Cannot connect to proxy.', timeout('_ssl.c:1114: The handshake operation timed out')))"), '(Request ID: 960233b9-db54-43d3-ad1e-c2bc38f02163)')' thrown while requesting GET https://cdn-lfs.huggingface.co/repos/76/61/766109d3d0b4ee837dfedfab0527ead28aab8af261c2eacbb3c7f7e5d3676920/a8702498162c95d68d2724e7f333c83d7be08de81cfc091455c38730682116d3?response-content-disposition=attachment%3B+filename*%3DUTF-8%27%27model.safetensors%3B+filename%3D%22model.safetensors%22%3B&Expires=1699957534&Policy=eyJTdGF0ZW1lbnQiOlt7IkNvbmRpdGlvbiI6eyJEYXRlTGVzc1RoYW4iOnsiQVdTOkVwb2NoVGltZSI6MTY5OTk1NzUzNH19LCJSZXNvdXJjZSI6Imh0dHBzOi8vY2RuLWxmcy5odWdnaW5nZmFjZS5jby9yZXBvcy83Ni82MS83NjYxMDlkM2QwYjRlZTgzN2RmZWRmYWIwNTI3ZWFkMjhhYWI4YWYyNjFjMmVhY2JiM2M3ZjdlNWQzNjc2OTIwL2E4NzAyNDk4MTYyYzk1ZDY4ZDI3MjRlN2YzMzNjODNkN2JlMDhkZTgxY2ZjMDkxNDU1YzM4NzMwNjgyMTE2ZDM%7EcmVzcG9uc2UtY29udGVudC1kaXNwb3NpdGlvbj0qIn1dfQ__&Signature=i5kimBqXmYWtdf51gu4VaAOWpTuLRxhB76R2ER4mL9v%7ERigg7U%7EhYJl6Db1lUT39xOo6VddwNnKCwyrNG8wJI4hBPgzWoCnb0TSsm%7E9k1fMG57ommM0g3iEfNc58nEeKZtpW%7EuMgxgz54XVIiDozNIMGAT4UKbPvx9tVvosKHkrL890T3LWG-mFt65%7EknuRqSIM3EYtH71ve6r92llPK-T84l7zzUp8KxKQ8BPIBB7%7E3p5Oe-ArCyhWMoPbmthhjdYWZjMnm6u8fyioWBVs8Xvsrb6pExuD3eiBTPr7PfC4%7Es%7EjZB2nEoqyQZfItkt94djcNI2P255E%7EZoAZVL1XKA__&Key-Pair-Id=KVTP0A1DKRTAX
Traceback (most recent call last):
  File "./f00305_generate_tweet.py", line 43, in <module>
    test_generate_tweet()
  File "./f00305_generate_tweet.py", line 27, in test_generate_tweet
    tweet1 = generate_tweet('The Future of AI in Education')
  File "./f00305_generate_tweet.py", line 17, in generate_tweet
    generator = pipeline('text-generation', model='bigscience/bloom-560m')
  File "/root/miniconda3/envs/py38/lib/python3.8/site-packages/transformers/pipelines/__init__.py", line 824, in pipeline
    framework, model = infer_framework_load_model(
  File "/root/miniconda3/envs/py38/lib/python3.8/site-packages/transformers/pipelines/base.py", line 282, in infer_framework_load_model
    raise ValueError(
ValueError: Could not load model bigscience/bloom-560m with any of the following classes: (<class 'transformers.models.auto.modeling_auto.AutoModelForCausalLM'>, <class 'transformers.models.bloom.modeling_bloom.BloomForCausalLM'>). See the original errors:

while loading with AutoModelForCausalLM, an error is thrown:
Traceback (most recent call last):
  File "/root/miniconda3/envs/py38/lib/python3.8/site-packages/huggingface_hub/utils/_errors.py", line 261, in hf_raise_for_status
    response.raise_for_status()
  File "/root/miniconda3/envs/py38/lib/python3.8/site-packages/requests/models.py", line 1021, in raise_for_status
    raise HTTPError(http_error_msg, response=self)
requests.exceptions.HTTPError: 503 Server Error: Service Unavailable for url: https://cdn-lfs.huggingface.co/repos/76/61/766109d3d0b4ee837dfedfab0527ead28aab8af261c2eacbb3c7f7e5d3676920/a8702498162c95d68d2724e7f333c83d7be08de81cfc091455c38730682116d3?response-content-disposition=attachment%3B+filename*%3DUTF-8%27%27model.safetensors%3B+filename%3D%22model.safetensors%22%3B&Expires=1699956644&Policy=eyJTdGF0ZW1lbnQiOlt7IkNvbmRpdGlvbiI6eyJEYXRlTGVzc1RoYW4iOnsiQVdTOkVwb2NoVGltZSI6MTY5OTk1NjY0NH19LCJSZXNvdXJjZSI6Imh0dHBzOi8vY2RuLWxmcy5odWdnaW5nZmFjZS5jby9yZXBvcy83Ni82MS83NjYxMDlkM2QwYjRlZTgzN2RmZWRmYWIwNTI3ZWFkMjhhYWI4YWYyNjFjMmVhY2JiM2M3ZjdlNWQzNjc2OTIwL2E4NzAyNDk4MTYyYzk1ZDY4ZDI3MjRlN2YzMzNjODNkN2JlMDhkZTgxY2ZjMDkxNDU1YzM4NzMwNjgyMTE2ZDM~cmVzcG9uc2UtY29udGVudC1kaXNwb3NpdGlvbj0qIn1dfQ__&Signature=Ty1KewrUWfOJNN1kBGGMmU3BsBfvWSZqgqYHNjmqUonU~HefHf4R5ZnrlBgZw6Sb2SuQonZki1W2a4fPkLN0R8wdlJpPzSvUvxM4ghjgmeiKvZqbBt-PkZCrlGXetoQq72rUFOiR~tLfo9HgUTRPcZZk6YQD0bJoPvfv0sJoT5Ib08QJ3UzXXfPFgRR8DHeb~jY71OI71zLHhy9tV0gigPJfK5BP71Ii2bsNIQeiSxJJicP1C5zzPpS63m7aNwkcYu8JA1UwWsdeIzlhyZTwZhOwBW3Mhdb9KnpID7P2YRY2yftFC-JAASJk1tz0z7W3p1osAxwOltlMb~cEiqmt~g__&Key-Pair-Id=KVTP0A1DKRTAX

The above exception was the direct cause of the following exception:

Traceback (most recent call last):
  File "/root/miniconda3/envs/py38/lib/python3.8/site-packages/transformers/utils/hub.py", line 429, in cached_file
    resolved_file = hf_hub_download(
  File "/root/miniconda3/envs/py38/lib/python3.8/site-packages/huggingface_hub/utils/_validators.py", line 118, in _inner_fn
    return fn(*args, **kwargs)
  File "/root/miniconda3/envs/py38/lib/python3.8/site-packages/huggingface_hub/file_download.py", line 1429, in hf_hub_download
    http_get(
  File "/root/miniconda3/envs/py38/lib/python3.8/site-packages/huggingface_hub/file_download.py", line 524, in http_get
    hf_raise_for_status(r)
  File "/root/miniconda3/envs/py38/lib/python3.8/site-packages/huggingface_hub/utils/_errors.py", line 303, in hf_raise_for_status
    raise HfHubHTTPError(str(e), response=response) from e
huggingface_hub.utils._errors.HfHubHTTPError: 503 Server Error: Service Unavailable for url: https://cdn-lfs.huggingface.co/repos/76/61/766109d3d0b4ee837dfedfab0527ead28aab8af261c2eacbb3c7f7e5d3676920/a8702498162c95d68d2724e7f333c83d7be08de81cfc091455c38730682116d3?response-content-disposition=attachment%3B+filename*%3DUTF-8%27%27model.safetensors%3B+filename%3D%22model.safetensors%22%3B&Expires=1699956644&Policy=eyJTdGF0ZW1lbnQiOlt7IkNvbmRpdGlvbiI6eyJEYXRlTGVzc1RoYW4iOnsiQVdTOkVwb2NoVGltZSI6MTY5OTk1NjY0NH19LCJSZXNvdXJjZSI6Imh0dHBzOi8vY2RuLWxmcy5odWdnaW5nZmFjZS5jby9yZXBvcy83Ni82MS83NjYxMDlkM2QwYjRlZTgzN2RmZWRmYWIwNTI3ZWFkMjhhYWI4YWYyNjFjMmVhY2JiM2M3ZjdlNWQzNjc2OTIwL2E4NzAyNDk4MTYyYzk1ZDY4ZDI3MjRlN2YzMzNjODNkN2JlMDhkZTgxY2ZjMDkxNDU1YzM4NzMwNjgyMTE2ZDM~cmVzcG9uc2UtY29udGVudC1kaXNwb3NpdGlvbj0qIn1dfQ__&Signature=Ty1KewrUWfOJNN1kBGGMmU3BsBfvWSZqgqYHNjmqUonU~HefHf4R5ZnrlBgZw6Sb2SuQonZki1W2a4fPkLN0R8wdlJpPzSvUvxM4ghjgmeiKvZqbBt-PkZCrlGXetoQq72rUFOiR~tLfo9HgUTRPcZZk6YQD0bJoPvfv0sJoT5Ib08QJ3UzXXfPFgRR8DHeb~jY71OI71zLHhy9tV0gigPJfK5BP71Ii2bsNIQeiSxJJicP1C5zzPpS63m7aNwkcYu8JA1UwWsdeIzlhyZTwZhOwBW3Mhdb9KnpID7P2YRY2yftFC-JAASJk1tz0z7W3p1osAxwOltlMb~cEiqmt~g__&Key-Pair-Id=KVTP0A1DKRTAX

During handling of the above exception, another exception occurred:

Traceback (most recent call last):
  File "/root/miniconda3/envs/py38/lib/python3.8/site-packages/transformers/pipelines/base.py", line 269, in infer_framework_load_model
    model = model_class.from_pretrained(model, **kwargs)
  File "/root/miniconda3/envs/py38/lib/python3.8/site-packages/transformers/models/auto/auto_factory.py", line 563, in from_pretrained
    return model_class.from_pretrained(
  File "/root/miniconda3/envs/py38/lib/python3.8/site-packages/transformers/modeling_utils.py", line 2773, in from_pretrained
    resolved_archive_file = cached_file(pretrained_model_name_or_path, filename, **cached_file_kwargs)
  File "/root/miniconda3/envs/py38/lib/python3.8/site-packages/transformers/utils/hub.py", line 492, in cached_file
    raise EnvironmentError(f"There was a specific connection error when trying to load {path_or_repo_id}:\n{err}")
OSError: There was a specific connection error when trying to load bigscience/bloom-560m:
503 Server Error: Service Unavailable for url: https://cdn-lfs.huggingface.co/repos/76/61/766109d3d0b4ee837dfedfab0527ead28aab8af261c2eacbb3c7f7e5d3676920/a8702498162c95d68d2724e7f333c83d7be08de81cfc091455c38730682116d3?response-content-disposition=attachment%3B+filename*%3DUTF-8%27%27model.safetensors%3B+filename%3D%22model.safetensors%22%3B&Expires=1699956644&Policy=eyJTdGF0ZW1lbnQiOlt7IkNvbmRpdGlvbiI6eyJEYXRlTGVzc1RoYW4iOnsiQVdTOkVwb2NoVGltZSI6MTY5OTk1NjY0NH19LCJSZXNvdXJjZSI6Imh0dHBzOi8vY2RuLWxmcy5odWdnaW5nZmFjZS5jby9yZXBvcy83Ni82MS83NjYxMDlkM2QwYjRlZTgzN2RmZWRmYWIwNTI3ZWFkMjhhYWI4YWYyNjFjMmVhY2JiM2M3ZjdlNWQzNjc2OTIwL2E4NzAyNDk4MTYyYzk1ZDY4ZDI3MjRlN2YzMzNjODNkN2JlMDhkZTgxY2ZjMDkxNDU1YzM4NzMwNjgyMTE2ZDM~cmVzcG9uc2UtY29udGVudC1kaXNwb3NpdGlvbj0qIn1dfQ__&Signature=Ty1KewrUWfOJNN1kBGGMmU3BsBfvWSZqgqYHNjmqUonU~HefHf4R5ZnrlBgZw6Sb2SuQonZki1W2a4fPkLN0R8wdlJpPzSvUvxM4ghjgmeiKvZqbBt-PkZCrlGXetoQq72rUFOiR~tLfo9HgUTRPcZZk6YQD0bJoPvfv0sJoT5Ib08QJ3UzXXfPFgRR8DHeb~jY71OI71zLHhy9tV0gigPJfK5BP71Ii2bsNIQeiSxJJicP1C5zzPpS63m7aNwkcYu8JA1UwWsdeIzlhyZTwZhOwBW3Mhdb9KnpID7P2YRY2yftFC-JAASJk1tz0z7W3p1osAxwOltlMb~cEiqmt~g__&Key-Pair-Id=KVTP0A1DKRTAX

while loading with BloomForCausalLM, an error is thrown:
Traceback (most recent call last):
  File "/root/miniconda3/envs/py38/lib/python3.8/site-packages/urllib3/connectionpool.py", line 712, in urlopen
    self._prepare_proxy(conn)
  File "/root/miniconda3/envs/py38/lib/python3.8/site-packages/urllib3/connectionpool.py", line 1012, in _prepare_proxy
    conn.connect()
  File "/root/miniconda3/envs/py38/lib/python3.8/site-packages/urllib3/connection.py", line 419, in connect
    self.sock = ssl_wrap_socket(
  File "/root/miniconda3/envs/py38/lib/python3.8/site-packages/urllib3/util/ssl_.py", line 449, in ssl_wrap_socket
    ssl_sock = _ssl_wrap_socket_impl(
  File "/root/miniconda3/envs/py38/lib/python3.8/site-packages/urllib3/util/ssl_.py", line 493, in _ssl_wrap_socket_impl
    return ssl_context.wrap_socket(sock, server_hostname=server_hostname)
  File "/root/miniconda3/envs/py38/lib/python3.8/ssl.py", line 500, in wrap_socket
    return self.sslsocket_class._create(
  File "/root/miniconda3/envs/py38/lib/python3.8/ssl.py", line 1073, in _create
    self.do_handshake()
  File "/root/miniconda3/envs/py38/lib/python3.8/ssl.py", line 1342, in do_handshake
    self._sslobj.do_handshake()
socket.timeout: _ssl.c:1114: The handshake operation timed out

During handling of the above exception, another exception occurred:

Traceback (most recent call last):
  File "/root/miniconda3/envs/py38/lib/python3.8/site-packages/requests/adapters.py", line 486, in send
    resp = conn.urlopen(
  File "/root/miniconda3/envs/py38/lib/python3.8/site-packages/urllib3/connectionpool.py", line 799, in urlopen
    retries = retries.increment(
  File "/root/miniconda3/envs/py38/lib/python3.8/site-packages/urllib3/util/retry.py", line 592, in increment
    raise MaxRetryError(_pool, url, error or ResponseError(cause))
urllib3.exceptions.MaxRetryError: HTTPSConnectionPool(host='cdn-lfs.huggingface.co', port=443): Max retries exceeded with url: /repos/76/61/766109d3d0b4ee837dfedfab0527ead28aab8af261c2eacbb3c7f7e5d3676920/a8702498162c95d68d2724e7f333c83d7be08de81cfc091455c38730682116d3?response-content-disposition=attachment%3B+filename*%3DUTF-8%27%27model.safetensors%3B+filename%3D%22model.safetensors%22%3B&Expires=1699957534&Policy=eyJTdGF0ZW1lbnQiOlt7IkNvbmRpdGlvbiI6eyJEYXRlTGVzc1RoYW4iOnsiQVdTOkVwb2NoVGltZSI6MTY5OTk1NzUzNH19LCJSZXNvdXJjZSI6Imh0dHBzOi8vY2RuLWxmcy5odWdnaW5nZmFjZS5jby9yZXBvcy83Ni82MS83NjYxMDlkM2QwYjRlZTgzN2RmZWRmYWIwNTI3ZWFkMjhhYWI4YWYyNjFjMmVhY2JiM2M3ZjdlNWQzNjc2OTIwL2E4NzAyNDk4MTYyYzk1ZDY4ZDI3MjRlN2YzMzNjODNkN2JlMDhkZTgxY2ZjMDkxNDU1YzM4NzMwNjgyMTE2ZDM~cmVzcG9uc2UtY29udGVudC1kaXNwb3NpdGlvbj0qIn1dfQ__&Signature=i5kimBqXmYWtdf51gu4VaAOWpTuLRxhB76R2ER4mL9v~Rigg7U~hYJl6Db1lUT39xOo6VddwNnKCwyrNG8wJI4hBPgzWoCnb0TSsm~9k1fMG57ommM0g3iEfNc58nEeKZtpW~uMgxgz54XVIiDozNIMGAT4UKbPvx9tVvosKHkrL890T3LWG-mFt65~knuRqSIM3EYtH71ve6r92llPK-T84l7zzUp8KxKQ8BPIBB7~3p5Oe-ArCyhWMoPbmthhjdYWZjMnm6u8fyioWBVs8Xvsrb6pExuD3eiBTPr7PfC4~s~jZB2nEoqyQZfItkt94djcNI2P255E~ZoAZVL1XKA__&Key-Pair-Id=KVTP0A1DKRTAX (Caused by ProxyError('Cannot connect to proxy.', timeout('_ssl.c:1114: The handshake operation timed out')))

During handling of the above exception, another exception occurred:

Traceback (most recent call last):
  File "/root/miniconda3/envs/py38/lib/python3.8/site-packages/transformers/pipelines/base.py", line 269, in infer_framework_load_model
    model = model_class.from_pretrained(model, **kwargs)
  File "/root/miniconda3/envs/py38/lib/python3.8/site-packages/transformers/modeling_utils.py", line 2773, in from_pretrained
    resolved_archive_file = cached_file(pretrained_model_name_or_path, filename, **cached_file_kwargs)
  File "/root/miniconda3/envs/py38/lib/python3.8/site-packages/transformers/utils/hub.py", line 429, in cached_file
    resolved_file = hf_hub_download(
  File "/root/miniconda3/envs/py38/lib/python3.8/site-packages/huggingface_hub/utils/_validators.py", line 118, in _inner_fn
    return fn(*args, **kwargs)
  File "/root/miniconda3/envs/py38/lib/python3.8/site-packages/huggingface_hub/file_download.py", line 1429, in hf_hub_download
    http_get(
  File "/root/miniconda3/envs/py38/lib/python3.8/site-packages/huggingface_hub/file_download.py", line 515, in http_get
    r = _request_wrapper(
  File "/root/miniconda3/envs/py38/lib/python3.8/site-packages/huggingface_hub/file_download.py", line 452, in _request_wrapper
    return http_backoff(
  File "/root/miniconda3/envs/py38/lib/python3.8/site-packages/huggingface_hub/utils/_http.py", line 274, in http_backoff
    raise err
  File "/root/miniconda3/envs/py38/lib/python3.8/site-packages/huggingface_hub/utils/_http.py", line 258, in http_backoff
    response = session.request(method=method, url=url, **kwargs)
  File "/root/miniconda3/envs/py38/lib/python3.8/site-packages/requests/sessions.py", line 589, in request
    resp = self.send(prep, **send_kwargs)
  File "/root/miniconda3/envs/py38/lib/python3.8/site-packages/requests/sessions.py", line 703, in send
    r = adapter.send(request, **kwargs)
  File "/root/miniconda3/envs/py38/lib/python3.8/site-packages/huggingface_hub/utils/_http.py", line 63, in send
    return super().send(request, *args, **kwargs)
  File "/root/miniconda3/envs/py38/lib/python3.8/site-packages/requests/adapters.py", line 513, in send
    raise ProxyError(e, request=request)
requests.exceptions.ProxyError: (MaxRetryError("HTTPSConnectionPool(host='cdn-lfs.huggingface.co', port=443): Max retries exceeded with url: /repos/76/61/766109d3d0b4ee837dfedfab0527ead28aab8af261c2eacbb3c7f7e5d3676920/a8702498162c95d68d2724e7f333c83d7be08de81cfc091455c38730682116d3?response-content-disposition=attachment%3B+filename*%3DUTF-8%27%27model.safetensors%3B+filename%3D%22model.safetensors%22%3B&Expires=1699957534&Policy=eyJTdGF0ZW1lbnQiOlt7IkNvbmRpdGlvbiI6eyJEYXRlTGVzc1RoYW4iOnsiQVdTOkVwb2NoVGltZSI6MTY5OTk1NzUzNH19LCJSZXNvdXJjZSI6Imh0dHBzOi8vY2RuLWxmcy5odWdnaW5nZmFjZS5jby9yZXBvcy83Ni82MS83NjYxMDlkM2QwYjRlZTgzN2RmZWRmYWIwNTI3ZWFkMjhhYWI4YWYyNjFjMmVhY2JiM2M3ZjdlNWQzNjc2OTIwL2E4NzAyNDk4MTYyYzk1ZDY4ZDI3MjRlN2YzMzNjODNkN2JlMDhkZTgxY2ZjMDkxNDU1YzM4NzMwNjgyMTE2ZDM~cmVzcG9uc2UtY29udGVudC1kaXNwb3NpdGlvbj0qIn1dfQ__&Signature=i5kimBqXmYWtdf51gu4VaAOWpTuLRxhB76R2ER4mL9v~Rigg7U~hYJl6Db1lUT39xOo6VddwNnKCwyrNG8wJI4hBPgzWoCnb0TSsm~9k1fMG57ommM0g3iEfNc58nEeKZtpW~uMgxgz54XVIiDozNIMGAT4UKbPvx9tVvosKHkrL890T3LWG-mFt65~knuRqSIM3EYtH71ve6r92llPK-T84l7zzUp8KxKQ8BPIBB7~3p5Oe-ArCyhWMoPbmthhjdYWZjMnm6u8fyioWBVs8Xvsrb6pExuD3eiBTPr7PfC4~s~jZB2nEoqyQZfItkt94djcNI2P255E~ZoAZVL1XKA__&Key-Pair-Id=KVTP0A1DKRTAX (Caused by ProxyError('Cannot connect to proxy.', timeout('_ssl.c:1114: The handshake operation timed out')))"), '(Request ID: 960233b9-db54-43d3-ad1e-c2bc38f02163)')



