2023-11-12 02:39:44.662421: I tensorflow/core/util/port.cc:110] oneDNN custom operations are on. You may see slightly different numerical results due to floating-point round-off errors from different computation orders. To turn them off, set the environment variable `TF_ENABLE_ONEDNN_OPTS=0`.
2023-11-12 02:39:44.704651: I tensorflow/core/platform/cpu_feature_guard.cc:182] This TensorFlow binary is optimized to use available CPU instructions in performance-critical operations.
To enable the following instructions: AVX2 AVX512F AVX512_VNNI FMA, in other operations, rebuild TensorFlow with the appropriate compiler flags.
2023-11-12 02:39:45.366694: W tensorflow/compiler/tf2tensorrt/utils/py_utils.cc:38] TF-TRT Warning: Could not find TensorRT
'(ReadTimeoutError("HTTPSConnectionPool(host='huggingface.co', port=443): Read timed out. (read timeout=10)"), '(Request ID: 9c41ab9d-9200-4471-a76d-76ab838238fa)')' thrown while requesting HEAD https://huggingface.co/facebook/timesformer-base-finetuned-k600/resolve/main/preprocessor_config.json
Traceback (most recent call last):
  File "/root/miniconda3/envs/py38/lib/python3.8/site-packages/urllib3/connectionpool.py", line 467, in _make_request
    six.raise_from(e, None)
  File "<string>", line 3, in raise_from
  File "/root/miniconda3/envs/py38/lib/python3.8/site-packages/urllib3/connectionpool.py", line 462, in _make_request
    httplib_response = conn.getresponse()
  File "/root/miniconda3/envs/py38/lib/python3.8/http/client.py", line 1348, in getresponse
    response.begin()
  File "/root/miniconda3/envs/py38/lib/python3.8/http/client.py", line 316, in begin
    version, status, reason = self._read_status()
  File "/root/miniconda3/envs/py38/lib/python3.8/http/client.py", line 277, in _read_status
    line = str(self.fp.readline(_MAXLINE + 1), "iso-8859-1")
  File "/root/miniconda3/envs/py38/lib/python3.8/socket.py", line 669, in readinto
    return self._sock.recv_into(b)
  File "/root/miniconda3/envs/py38/lib/python3.8/ssl.py", line 1274, in recv_into
    return self.read(nbytes, buffer)
  File "/root/miniconda3/envs/py38/lib/python3.8/ssl.py", line 1132, in read
    return self._sslobj.read(len, buffer)
socket.timeout: The read operation timed out

During handling of the above exception, another exception occurred:

Traceback (most recent call last):
  File "/root/miniconda3/envs/py38/lib/python3.8/site-packages/requests/adapters.py", line 486, in send
    resp = conn.urlopen(
  File "/root/miniconda3/envs/py38/lib/python3.8/site-packages/urllib3/connectionpool.py", line 799, in urlopen
    retries = retries.increment(
  File "/root/miniconda3/envs/py38/lib/python3.8/site-packages/urllib3/util/retry.py", line 550, in increment
    raise six.reraise(type(error), error, _stacktrace)
  File "/root/miniconda3/envs/py38/lib/python3.8/site-packages/urllib3/packages/six.py", line 770, in reraise
    raise value
  File "/root/miniconda3/envs/py38/lib/python3.8/site-packages/urllib3/connectionpool.py", line 715, in urlopen
    httplib_response = self._make_request(
  File "/root/miniconda3/envs/py38/lib/python3.8/site-packages/urllib3/connectionpool.py", line 469, in _make_request
    self._raise_timeout(err=e, url=url, timeout_value=read_timeout)
  File "/root/miniconda3/envs/py38/lib/python3.8/site-packages/urllib3/connectionpool.py", line 358, in _raise_timeout
    raise ReadTimeoutError(
urllib3.exceptions.ReadTimeoutError: HTTPSConnectionPool(host='huggingface.co', port=443): Read timed out. (read timeout=10)

During handling of the above exception, another exception occurred:

Traceback (most recent call last):
  File "/root/miniconda3/envs/py38/lib/python3.8/site-packages/huggingface_hub/file_download.py", line 1230, in hf_hub_download
    metadata = get_hf_file_metadata(
  File "/root/miniconda3/envs/py38/lib/python3.8/site-packages/huggingface_hub/utils/_validators.py", line 118, in _inner_fn
    return fn(*args, **kwargs)
  File "/root/miniconda3/envs/py38/lib/python3.8/site-packages/huggingface_hub/file_download.py", line 1597, in get_hf_file_metadata
    r = _request_wrapper(
  File "/root/miniconda3/envs/py38/lib/python3.8/site-packages/huggingface_hub/file_download.py", line 417, in _request_wrapper
    response = _request_wrapper(
  File "/root/miniconda3/envs/py38/lib/python3.8/site-packages/huggingface_hub/file_download.py", line 452, in _request_wrapper
    return http_backoff(
  File "/root/miniconda3/envs/py38/lib/python3.8/site-packages/huggingface_hub/utils/_http.py", line 274, in http_backoff
    raise err
  File "/root/miniconda3/envs/py38/lib/python3.8/site-packages/huggingface_hub/utils/_http.py", line 258, in http_backoff
    response = session.request(method=method, url=url, **kwargs)
  File "/root/miniconda3/envs/py38/lib/python3.8/site-packages/requests/sessions.py", line 589, in request
    resp = self.send(prep, **send_kwargs)
  File "/root/miniconda3/envs/py38/lib/python3.8/site-packages/requests/sessions.py", line 703, in send
    r = adapter.send(request, **kwargs)
  File "/root/miniconda3/envs/py38/lib/python3.8/site-packages/huggingface_hub/utils/_http.py", line 63, in send
    return super().send(request, *args, **kwargs)
  File "/root/miniconda3/envs/py38/lib/python3.8/site-packages/requests/adapters.py", line 532, in send
    raise ReadTimeout(e, request=request)
requests.exceptions.ReadTimeout: (ReadTimeoutError("HTTPSConnectionPool(host='huggingface.co', port=443): Read timed out. (read timeout=10)"), '(Request ID: 9c41ab9d-9200-4471-a76d-76ab838238fa)')

The above exception was the direct cause of the following exception:

Traceback (most recent call last):
  File "/root/miniconda3/envs/py38/lib/python3.8/site-packages/transformers/utils/hub.py", line 429, in cached_file
    resolved_file = hf_hub_download(
  File "/root/miniconda3/envs/py38/lib/python3.8/site-packages/huggingface_hub/utils/_validators.py", line 118, in _inner_fn
    return fn(*args, **kwargs)
  File "/root/miniconda3/envs/py38/lib/python3.8/site-packages/huggingface_hub/file_download.py", line 1347, in hf_hub_download
    raise LocalEntryNotFoundError(
huggingface_hub.utils._errors.LocalEntryNotFoundError: An error happened while trying to locate the file on the Hub and we cannot find the requested files in the local cache. Please check your connection and try again or make sure your Internet connection is on.

The above exception was the direct cause of the following exception:

Traceback (most recent call last):
  File "./f00479_classify_advertisement_video.py", line 44, in <module>
    test_classify_advertisement_video()
  File "./f00479_classify_advertisement_video.py", line 38, in test_classify_advertisement_video
    predicted_class = classify_advertisement_video(video)
  File "./f00479_classify_advertisement_video.py", line 22, in classify_advertisement_video
    processor = AutoImageProcessor.from_pretrained('facebook/timesformer-base-finetuned-k600')
  File "/root/miniconda3/envs/py38/lib/python3.8/site-packages/transformers/models/auto/image_processing_auto.py", line 344, in from_pretrained
    config_dict, _ = ImageProcessingMixin.get_image_processor_dict(pretrained_model_name_or_path, **kwargs)
  File "/root/miniconda3/envs/py38/lib/python3.8/site-packages/transformers/image_processing_utils.py", line 329, in get_image_processor_dict
    resolved_image_processor_file = cached_file(
  File "/root/miniconda3/envs/py38/lib/python3.8/site-packages/transformers/utils/hub.py", line 469, in cached_file
    raise EnvironmentError(
OSError: We couldn't connect to 'https://huggingface.co' to load this file, couldn't find it in the cached files and it looks like facebook/timesformer-base-finetuned-k600 is not the path to a directory containing a file named preprocessor_config.json.
Checkout your internet connection or see how to run the library in offline mode at 'https://huggingface.co/docs/transformers/installation#offline-mode'.
