Traceback (most recent call last):
  File "/root/miniconda3/envs/py38/lib/python3.8/site-packages/huggingface_hub/utils/_errors.py", line 261, in hf_raise_for_status
    response.raise_for_status()
  File "/root/miniconda3/envs/py38/lib/python3.8/site-packages/requests/models.py", line 1021, in raise_for_status
    raise HTTPError(http_error_msg, response=self)
requests.exceptions.HTTPError: 401 Client Error: Unauthorized for url: https://huggingface.co/joeddav/xlm-roberta-large-xnli/resolve/main/config.json

The above exception was the direct cause of the following exception:

Traceback (most recent call last):
  File "/root/miniconda3/envs/py38/lib/python3.8/site-packages/transformers/utils/hub.py", line 430, in cached_file
    resolved_file = hf_hub_download(
  File "/root/miniconda3/envs/py38/lib/python3.8/site-packages/huggingface_hub/utils/_validators.py", line 118, in _inner_fn
    return fn(*args, **kwargs)
  File "/root/miniconda3/envs/py38/lib/python3.8/site-packages/huggingface_hub/file_download.py", line 1346, in hf_hub_download
    raise head_call_error
  File "/root/miniconda3/envs/py38/lib/python3.8/site-packages/huggingface_hub/file_download.py", line 1232, in hf_hub_download
    metadata = get_hf_file_metadata(
  File "/root/miniconda3/envs/py38/lib/python3.8/site-packages/huggingface_hub/utils/_validators.py", line 118, in _inner_fn
    return fn(*args, **kwargs)
  File "/root/miniconda3/envs/py38/lib/python3.8/site-packages/huggingface_hub/file_download.py", line 1608, in get_hf_file_metadata
    hf_raise_for_status(r)
  File "/root/miniconda3/envs/py38/lib/python3.8/site-packages/huggingface_hub/utils/_errors.py", line 277, in hf_raise_for_status
    raise GatedRepoError(message, response) from e
huggingface_hub.utils._errors.GatedRepoError: 401 Client Error. (Request ID: Root=1-65508d26-1c2ff0720c74a80d43c268f2;0480e3f0-6274-417a-a50d-33f4ab4aa599)

Cannot access gated repo for url https://huggingface.co/joeddav/xlm-roberta-large-xnli/resolve/main/config.json.
Repo model joeddav/xlm-roberta-large-xnli is gated. You must be authenticated to access it.

The above exception was the direct cause of the following exception:

Traceback (most recent call last):
  File "./f00780_classify_inquiry.py", line 45, in <module>
    test_classify_inquiry()
  File "./f00780_classify_inquiry.py", line 31, in test_classify_inquiry
    assert classify_inquiry(test_inquiry1) == expected_result1
  File "./f00780_classify_inquiry.py", line 17, in classify_inquiry
    classifier = pipeline('zero-shot-classification', model='joeddav/xlm-roberta-large-xnli')
  File "/root/miniconda3/envs/py38/lib/python3.8/site-packages/transformers/pipelines/__init__.py", line 747, in pipeline
    resolved_config_file = cached_file(
  File "/root/miniconda3/envs/py38/lib/python3.8/site-packages/transformers/utils/hub.py", line 445, in cached_file
    raise EnvironmentError(
OSError: You are trying to access a gated repo.
Make sure to request access at https://huggingface.co/joeddav/xlm-roberta-large-xnli and pass a token having permission to this repo either by logging in with `huggingface-cli login` or by passing `token=<your_token>`.
