Traceback (most recent call last):
  File "/root/miniconda3/envs/py38/lib/python3.8/site-packages/huggingface_hub/utils/_errors.py", line 261, in hf_raise_for_status
    response.raise_for_status()
  File "/root/miniconda3/envs/py38/lib/python3.8/site-packages/requests/models.py", line 1021, in raise_for_status
    raise HTTPError(http_error_msg, response=self)
requests.exceptions.HTTPError: 401 Client Error: Unauthorized for url: https://huggingface.co/microsoft/swin-tiny-patch4-window7-224-bottom_cleaned_data/resolve/main/config.json

The above exception was the direct cause of the following exception:

Traceback (most recent call last):
  File "/root/miniconda3/envs/py38/lib/python3.8/site-packages/transformers/utils/hub.py", line 430, in cached_file
    resolved_file = hf_hub_download(
  File "/root/miniconda3/envs/py38/lib/python3.8/site-packages/huggingface_hub/utils/_validators.py", line 118, in _inner_fn
    return fn(*args, **kwargs)
  File "/root/miniconda3/envs/py38/lib/python3.8/site-packages/huggingface_hub/file_download.py", line 1346, in hf_hub_download
    raise head_call_error
  File "/root/miniconda3/envs/py38/lib/python3.8/site-packages/huggingface_hub/file_download.py", line 1232, in hf_hub_download
    metadata = get_hf_file_metadata(
  File "/root/miniconda3/envs/py38/lib/python3.8/site-packages/huggingface_hub/utils/_validators.py", line 118, in _inner_fn
    return fn(*args, **kwargs)
  File "/root/miniconda3/envs/py38/lib/python3.8/site-packages/huggingface_hub/file_download.py", line 1608, in get_hf_file_metadata
    hf_raise_for_status(r)
  File "/root/miniconda3/envs/py38/lib/python3.8/site-packages/huggingface_hub/utils/_errors.py", line 293, in hf_raise_for_status
    raise RepositoryNotFoundError(message, response) from e
huggingface_hub.utils._errors.RepositoryNotFoundError: 401 Client Error. (Request ID: Root=1-65509eec-64297dff273922fc12ea8e31;107d567e-18cb-4ced-aa42-8706e6082703)

Repository Not Found for url: https://huggingface.co/microsoft/swin-tiny-patch4-window7-224-bottom_cleaned_data/resolve/main/config.json.
Please make sure you specified the correct `repo_id` and `repo_type`.
If you are trying to access a private or gated repo, make sure you are authenticated.
Invalid username or password.

The above exception was the direct cause of the following exception:

Traceback (most recent call last):
  File "./f00841_classify_images.py", line 51, in <module>
    test_classify_images()
  File "./f00841_classify_images.py", line 41, in test_classify_images
    results = classify_images(image_urls, categories)
  File "./f00841_classify_images.py", line 22, in classify_images
    model = AutoModelForImageClassification.from_pretrained('microsoft/swin-tiny-patch4-window7-224-bottom_cleaned_data')
  File "/root/miniconda3/envs/py38/lib/python3.8/site-packages/transformers/models/auto/auto_factory.py", line 488, in from_pretrained
    resolved_config_file = cached_file(
  File "/root/miniconda3/envs/py38/lib/python3.8/site-packages/transformers/utils/hub.py", line 451, in cached_file
    raise EnvironmentError(
OSError: microsoft/swin-tiny-patch4-window7-224-bottom_cleaned_data is not a local folder and is not a valid model identifier listed on 'https://huggingface.co/models'
If this is a private repository, make sure to pass a token having permission to this repo either by logging in with `huggingface-cli login` or by passing `token=<your_token>`
